<?xml version="1.0" encoding="utf-8"?>
<robot name="phantom_touch" xmlns:xacro="http://www.ros.org/wiki/xacro">
	
	<!-- Materials -->
	<material name="metal_seamed">
		<color rgba="0.4627450980392157 0.4666666666666667 0.4509803921568628 1.0" />
	</material>
	<material name="blue">
		<color rgba="0.0 0.0 0.8 1.0" />
	</material>
	<material name="white">
		<color rgba="1.0 1.0 1.0 1.0" />
	</material>
	
  <link name="base" >
    <visual>
			<origin xyz="0 -0.02 0" />
      <geometry>
				<mesh filename="package://touch_description/meshes/base.stl" />
      </geometry>
      <material name="metal_seamed"/>
    </visual>
  </link>

  <!-- frame base_ref is set just as the base frame of Real Touch-->
  <!-- the bias is a approaximation -->
  <joint name="base_fixed" type="fixed" >
    <parent link="base" />
    <child link="base_ref" />
    <origin xyz="0 0.157 0.090" rpy="1.5708 0 3.1416" />
  </joint>

  <link name="base_ref" />

  <joint name="waist" type="revolute" >
    <parent link="base" />
    <child link="torso" />
    <origin xyz="0 0 0.09" rpy="0 0 0" />
    <axis xyz="0 0 1" />
    <!-- range from 0.9844 to -0.9844 operation: negative -->
    <limit lower="-0.98" upper="0.98" velocity="100" effort="5" />
  </joint>

  <link name="torso" >
    <visual>
			<origin xyz="0 0 0.036" rpy="-1.5707 0 0"/>
      <geometry>
				<mesh filename="package://touch_description/meshes/torso.stl" />
      </geometry>
      <material name="blue"/>
    </visual>
  </link>

  <joint name="shoulder" type="revolute" >
    <parent link="torso" />
    <child link="upper_arm" />
    <origin xyz="-0.0075 0 0.035" rpy="0 0 0" />
    <axis xyz="1 0 0" />
    <limit lower="0" upper="1.75" velocity="100" effort="5" />
  </joint>

  <link name="upper_arm" >
		<visual>
			<origin xyz="0.0075 0 0" rpy="0 0 0"/>
      <geometry>
				<mesh filename="package://touch_description/meshes/upper_arm.stl" />
      </geometry>
      <material name="metal_seamed" />
    </visual>
  </link>

  <joint name="elbow" type="revolute" >
    <parent link="upper_arm" />
    <child link="lower_arm" />
    <origin xyz="0.0075 .134 0" rpy="-1.5 0 0" />
    <axis xyz="1 0 0" />
    <!-- <limit lower="-0.81" upper="1.25" velocity="100" effort="5" />  -->
    <!-- range from -0.81 to -1.25 limit upper value -->
    <limit lower="-0.81" upper="1.2" velocity="100" effort="5" /> 
  </joint>

  <link name="lower_arm" >
		<visual>
			<origin xyz="0 0 0" rpy="1.5707 0 0"/>
      <geometry>
				<mesh filename="package://touch_description/meshes/lower_arm.stl" />
      </geometry>
      <material name="metal_seamed" />
    </visual>
  </link>

  <joint name="yaw" type="revolute" >
    <parent link="lower_arm" />
    <child link="wrist" />
    <origin xyz="0 0.08 0" />
    <axis xyz="0 1 0" />
    <!-- <limit lower="3.92" upper="8.83" velocity="100" effort="5" /> -->
    <!-- range from 2.51 to -2.55 operation: negative -->
    <limit lower="-2.50" upper="2.50" velocity="100" effort="5" />
  </joint>

  <link name="wrist" >
		<visual>
			<origin xyz="0 0 0" rpy="3.14159 0 0"/>
      <geometry>
				<mesh filename="package://touch_description/meshes/wrist.stl" />
      </geometry>
      <material name="metal_seamed" />
    </visual>
  </link>

  <joint name="pitch" type="revolute" >
    <parent link="wrist" />
    <child link="tip" />
    <!-- <origin xyz="0 0.0525 0" rpy="0.5 0 0" /> -->
    <!-- change the zero point of joint (be perpendicular) -->
    <origin xyz="0 0.0525 0" rpy="0 0 0" />     
    <axis xyz="1 0 0" />
    <!-- <limit lower="-0.5" upper="1.75" velocity="100" effort="5" />  -->
    <!-- range from -1.49 to 0.97  operation: +1.49 -->
    <limit lower="0" upper="2.40" velocity="100" effort="5" />  
  </joint>

  <link name="tip" >
		<visual>
			<origin xyz="0 0 0" rpy="-1.5707 0 0"/>
      <geometry>
				<mesh filename="package://touch_description/meshes/tip.stl" />
      </geometry>
      <material name="metal_seamed" />
    </visual>
  </link>

  <joint name="roll" type="revolute" >
    <parent link="tip" />
    <child link="stylus" />
    <origin xyz="0 -0.023 0" rpy="3.14159 3.14159 0" />
    <axis xyz="0 1 0" />
    <!-- range from -2.61 to 2.61; no operation-->
    <limit lower="-2.58" upper="2.58" velocity="100" effort="5" />
  </joint>

  <link name="stylus" >
    <visual>
			<origin xyz="0 -0.033 0" rpy="1.5707 1.5707 0"/>
      <geometry>
				<mesh filename="package://touch_description/meshes/pen.stl" />
      </geometry>
      <material name="blue" />
    </visual>
  </link>

  <!-- frame stylus_ref is set as the end-effector frame of Real Touch-->
  <joint name="stylus_fixed" type="fixed" >
    <parent link="stylus" />
    <child link="stylus_ref" />
    <origin xyz="0 0 0" rpy="1.5708 0 0" />
  </joint>

  <!-- frame probe for tranform to the probe frame -->
  <!-- TODO: remain to be verified -->
  <link name="stylus_ref" />

  <joint name="probe_fixed" type="fixed" >
    <parent link="stylus_ref" />
    <child link="probe" />
    <origin xyz="0 0 0" rpy="3.14159 0 0" />
  </joint>

  <link name="probe" />

</robot>

